<?xml version="1.0"?>
<robot name="servingrobot" xmlns:xacro="http://ros.org/wiki/xacro">

  <xacro:property name="caster_radius" value="0.05"/>
  <xacro:property name="caster_length" value="0.05"/>
  <xacro:property name="wheel_radius" value="0.1"/>
  <xacro:property name="wheel_length" value="0.05"/>

  <!--base_footprint-->
  <link name="base_footprint">

    <visual>
        <origin xyz="0 0 0" rpy="0 0 0" />
        <geometry>
            <box size="0.001 0.001 0.001" />
        </geometry>
    </visual>
  </link>
  <joint name="base_link_joint" type="fixed">
    <origin xyz="0 0 ${wheel_radius + 0.8}" rpy="0 0 0" />
    <parent link="base_footprint"/>
    <child link="base_link" />
  </joint>

  <!--body-->
  <link name="base_link">
    <visual>
      <geometry>
        <box size="0.6 0.41 1.69"/>
      </geometry>
      <material name="aluminum">
        <color rgba="0.75 0.75 0.75 1"/>
      </material>
    </visual>
  </link>

  <!--caster-->
  <link name="front_left_caster">
    <visual>
      <geometry>
        <cylinder radius="${caster_radius}" length="${caster_length}"/>
      </geometry>
      <material name="aluminum"/>
    </visual>
  </link>
  <joint name="front_left_caster_joint" type="continuous">
    <axis xyz="0 0 1"/>
    <parent link="base_link"/>
    <child link="front_left_caster"/>
    <origin rpy="0 1.58 0" xyz="0.2 0.2 -0.85"/>
  </joint>
  <link name="front_right_caster">
    <visual>
      <geometry>
        <cylinder radius="${caster_radius}" length="${caster_length}"/>
      </geometry>
      <material name="aluminum"/>
    </visual>
  </link>
  <joint name="front_right_caster_joint" type="continuous">
    <axis xyz="0 0 1"/>
    <parent link="base_link"/>
    <child link="front_right_caster"/>
    <origin rpy="0 -1.58 0" xyz="-0.2 0.2 -0.85"/>
  </joint>

  <!--wheel-->
  <link name="front_left_wheel">
    <visual>
      <geometry>
        <cylinder radius="${wheel_radius}" length="${wheel_length}"/>
      </geometry>
      <material name="aluminum"/>
    </visual>
  </link>
  <joint name="front_left_wheel_joint" type="continuous">
    <axis xyz="0 0 1"/>
    <parent link="base_link"/>
    <child link="front_left_wheel"/>
    <origin rpy="0 -1.58 0" xyz="0.3 -0.2 -0.80"/>
  </joint>
  <link name="front_right_wheel">
    <visual>
      <geometry>
        <cylinder radius="${wheel_radius}" length="${wheel_length}"/>
      </geometry>
      <material name="aluminum"/>
    </visual>
  </link>
  <joint name="front_right_wheel_joint" type="continuous">
    <axis xyz="0 0 1"/>
    <parent link="base_link"/>
    <child link="front_right_wheel"/>
    <origin rpy="0 -1.58 0" xyz="-0.3 -0.2 -0.80"/>
  </joint>

</robot>
